<?xml version="1.0" ?>
<robot xmlns:xacro="http://www.ros.org/wiki/xacro"
       name="interfearence">

  <xacro:arg name="robotns" default="/"/>

  <link name="base_link"/>

  <gazebo>
    <!-- plugin to allow the robot to interface with ros_control -->
    <plugin name="gazebo_ros_control" filename="libgazebo_ros_control.so">
      <!-- the launch file will replace this with something sensible -->
      <robotNamespace>$(arg robotns)</robotNamespace>
    </plugin>
    <!-- plugin to simulate the electromagnet -->
    <plugin name="magnet" filename="libmagnet_plugin.so"/>
    <self_collide>false</self_collide>
  </gazebo>

  <material name="grey">
    <color rgba="0.2 0.2 0.2 1"/>
  </material>

  <material name="light_grey">
    <color rgba="0.7 0.7 0.7 1"/>
  </material>

  <material name="red">
    <color rgba="0.8 0.1 0.1 1"/>
  </material>

  <material name="black">
    <color rgba="0.0 0.0 0.0 1"/>
  </material>

  <link name="base_footprint">
    <inertial>
      <mass value="1.7923895668327776"/>
      <origin rpy="0 0 0" xyz="0.00178 0.02496 0.04945"/>
      <inertia ixx="0.010567555781567964" ixy="5.0178754500137904e-05" ixz="-0.0002784618841121355" iyy="0.010348269788112794" iyz="-0.0024424380725769257" izz="0.007947774757175114"/>
    </inertial>
    <collision name="base_footprint_collision">
      <origin rpy="0 0 0" xyz="0.00178 0.02496 0.04945"/>
      <geometry>
        <mesh filename="$(find interfearence-description)/meshes/CAD/base_link.stl" scale="0.001 0.001 0.001"/>
      </geometry>
    </collision>
    <visual name="base_footprint_visual">
      <origin rpy="0 0 0" xyz="0.00178 0.02496 0.04945"/>
      <geometry>
        <mesh filename="$(find interfearence-description)/meshes/CAD/base_link.stl" scale="0.001 0.001 0.001"/>
      </geometry>
      <material name="grey"/>
    </visual>
  </link>

  <gazebo reference="base_footprint">
    <mu1>0.2</mu1>
    <mu2>0.2</mu2>
    <maxVel>0.0</maxVel>
    <minDepth>0.001</minDepth>
    <material>Gazebo/DarkGrey</material>
  </gazebo>

  <joint name="base_footprint_joint" type="fixed">
    <parent link="base_link"/>
    <child link="base_footprint"/>
      <origin rpy="0 0 1.57" xyz="0 0 0"/>
  </joint>

  <link name="front_left_line_sensor">
    <inertial>
      <mass value="0.0019264925574452472"/>
      <origin rpy="0 0 0" xyz="0 0 0"/>
      <inertia ixx="6.993652466946195e-06" ixy="1.0312316193946486e-05" ixz="-1.0982148189863088e-06" iyy="1.5628527481642678e-05" iyz="7.28180547902703e-07" izz="2.2405591810555344e-05"/>
    </inertial>
    <collision name="front_left_line_sensor_collision">
      <geometry>
        <mesh filename="$(find interfearence-description)/meshes/CAD/front_left_line_sensor.stl" scale="0.001 0.001 0.001"/>
      </geometry>
    </collision>
    <visual name="front_left_line_sensor_visual">
      <geometry>
        <mesh filename="$(find interfearence-description)/meshes/CAD/front_left_line_sensor.stl" scale="0.001 0.001 0.001"/>
      </geometry>
      <material name="red"/>
    </visual>
  </link>

  <gazebo reference="front_left_line_sensor">
    <sensor name="front_left_line_sensor_sensor" type="camera">
      <camera name="front_left_camera">
        <image>
          <width>1</width>
          <height>1</height>
          <format>R8G8B8</format>
        </image>
        <clip>
          <near>0.002</near>
        </clip>
      </camera>
      <plugin name="front_left_edge_detector_plugin" 
              filename="libarena_edge_detection_plugin.so">
        <cameraName>front_left_camera</cameraName>
        <alwaysOn>true</alwaysOn>
        <updateRate>30</updateRate>
        <imageTopicName>rgb/image_raw</imageTopicName>
        <cameraInfoTopicName>rgb/camera_info</cameraInfoTopicName>
        <frameName>/$(arg robotns)/front_left_line_sensor</frameName>
        <topicName>/$(arg robotns)/edge_sensors/front_left</topicName>
        <upperThreshhold>0.52</upperThreshhold>
        <lowerThreshhold>0.42</lowerThreshhold>
      </plugin>
    </sensor>
    <material>Gazebo/Red</material>
  </gazebo>

  <joint name="front_left_line_sensor_joint" type="fixed">
    <parent link="base_footprint"/>
    <child link="front_left_line_sensor"/>
    <origin rpy="0 0 0" xyz="0.08972 -0.05966  0.000631"/>
  </joint>

  <link name="front_right_line_sensor">
    <inertial>
      <mass value="0.0019264905571713684"/>
      <origin rpy="0 0 0" xyz="0 0 0"/>
      <inertia ixx="6.993643279974907e-06" ixy="-1.031230419502541e-05" ixz="1.0982122999868543e-06" iyy="1.5628510731568552e-05" iyz="7.281787006486148e-07" izz="2.2405566649128356e-05"/>
    </inertial>
    <collision name="front_right_line_sensor_collision">
      <geometry>
        <mesh filename="$(find interfearence-description)/meshes/CAD/front_right_line_sensor.stl" scale="0.001 0.001 0.001"/>
      </geometry>
    </collision>
    <visual name="front_right_line_sensor_visual">
      <geometry>
        <mesh filename="$(find interfearence-description)/meshes/CAD/front_right_line_sensor.stl" scale="0.001 0.001 0.001"/>
      </geometry>
      <material name="red"/>
    </visual>
  </link>

  <gazebo reference="front_right_line_sensor">
    <sensor name="front_right_line_sensor_sensor" type="camera">
      <camera name="front_right_camera">
        <image>
          <width>1</width>
          <height>1</height>
          <format>R8G8B8</format>
        </image>
        <clip>
          <near>0.002</near>
        </clip>
      </camera>
      <plugin name="front_right_edge_detector_plugin" 
              filename="libarena_edge_detection_plugin.so">
        <cameraName>front_right_camera</cameraName>
        <alwaysOn>true</alwaysOn>
        <updateRate>30</updateRate>
        <imageTopicName>rgb/image_raw</imageTopicName>
        <cameraInfoTopicName>rgb/camera_info</cameraInfoTopicName>
        <frameName>/$(arg robotns)/front_right_line_sensor</frameName>
        <topicName>/$(arg robotns)/edge_sensors/front_right</topicName>
        <upperThreshhold>0.52</upperThreshhold>
        <lowerThreshhold>0.42</lowerThreshhold>
      </plugin>
    </sensor>
    <material>Gazebo/Red</material>
  </gazebo>

  <joint name="front_right_line_sensor_joint" type="fixed">
    <parent link="base_footprint"/>
    <child link="front_right_line_sensor"/>
    <origin rpy="0 0 0" xyz="-0.08972 -0.05966  0.000631"/>
  </joint>

  <link name="front_scoop">
    <inertial>
      <mass value="0.3002793462422746"/>
      <origin rpy="0 0 0" xyz="0 0 0"/>
      <inertia ixx="0.0020069153294640834" ixy="-8.742216475555394e-10" ixz="1.1208629100778389e-09" iyy="0.0013842734355365178" iyz="0.00063334546461807" izz="0.002437143510894618"/>
    </inertial>
    <collision name="front_scoop_collision">
      <geometry>
        <mesh filename="$(find interfearence-description)/meshes/CAD/front_scoop.stl" scale="0.001 0.001 0.001"/>
      </geometry>
    </collision>
    <visual name="front_scoop_visual">
      <geometry>
        <mesh filename="$(find interfearence-description)/meshes/CAD/front_scoop.stl" scale="0.001 0.001 0.001"/>
      </geometry>
      <material name="light_grey"/>
    </visual>
  </link>

  <gazebo reference="front_scoop">
    <mu1>0.2</mu1>
    <mu2>0.2</mu2>
    <maxVel>0.0</maxVel>
    <minDepth>0.0005</minDepth>
    <material>Gazebo/Gold</material>
  </gazebo>

  <joint name="front_scoop_joint" type="fixed">
    <parent link="base_footprint"/>
    <child link="front_scoop"/>
    <origin rpy="0 0 0" xyz="0      -0.07125  0.03036"/>
  </joint>

  <link name="left_wheel">
    <inertial>
      <mass value="0.31653412374925943"/>
      <origin rpy="0 0 0" xyz="0 0 0"/>
      <inertia ixx="0.0014886350669894822" ixy="-0.0" ixz="-0.0" iyy="0.0013525795511995277" iyz="-0.0" izz="0.0014886350669894822"/>
    </inertial>
    <collision name="left_wheel_collision">
      <geometry>
        <mesh filename="$(find interfearence-description)/meshes/CAD/left_wheel.stl" scale="0.001 0.001 0.001"/>
      </geometry>
    </collision>
    <visual name="left_wheel_visual">
      <geometry>
        <mesh filename="$(find interfearence-description)/meshes/CAD/left_wheel.stl" scale="0.001 0.001 0.001"/>
      </geometry>
      <material name="red"/>
    </visual>
  </link>

  <gazebo reference="left_wheel">
    <mu1>0.9</mu1>
    <mu2>0.9</mu2>
    <maxVel>0.0</maxVel>
    <minDepth>0.001</minDepth>
    <material>Gazebo/Red</material>
  </gazebo>

  <joint name="left_wheel_joint" type="continuous">
    <parent link="base_footprint"/>
    <child link="left_wheel"/>
    <axis xyz="1 0 0"/>
    <origin rpy="0 0 0" xyz="0.0546  0.06201 0.02389"/>
    <limit effort="2.0"
           velocity="83.776"/>
  </joint>
  
  <transmission name="left_wheel_transmission">
    <type>transmission_interface/SimpleTransmission</type>
    <joint name="left_wheel_joint">
      <hardwareInterface>hardware_interface/EffortJointInterface</hardwareInterface>
    </joint>
    <actuator name="left_wheel_motor"/>
  </transmission>

  <link name="right_wheel">
    <inertial>
      <mass value="0.3165346352615723"/>
      <origin rpy="0 0 0" xyz="0 0 0"/>
      <inertia ixx="0.001488247009527325" ixy="0.0" ixz="0.0" iyy="0.0013525719181349898" iyz="-0.0" izz="0.001488247009527325"/>
    </inertial>
    <collision name="right_wheel_collision">
      <geometry>
        <mesh filename="$(find interfearence-description)/meshes/CAD/right_wheel.stl" scale="0.001 0.001 0.001"/>
      </geometry>
    </collision>
    <visual name="right_wheel_visual">
      <geometry>
        <mesh filename="$(find interfearence-description)/meshes/CAD/right_wheel.stl" scale="0.001 0.001 0.001"/>
      </geometry>
      <material name="red"/>
    </visual>
  </link>

  <gazebo reference="right_wheel">
    <mu1>0.9</mu1>
    <mu2>0.9</mu2>
    <maxVel>0.0</maxVel>
    <minDepth>0.001</minDepth>
    <material>Gazebo/Red</material>
  </gazebo>

  <joint name="right_wheel_joint" type="continuous">
    <parent link="base_footprint"/>
    <child link="right_wheel"/>
    <axis xyz="1 0 0"/>
    <origin rpy="0 0 0" xyz="-0.0546   0.062    0.02389"/>
    <limit effort="2.0"
           velocity="83.776"/>
  </joint>

  <transmission name="right_wheel_transmission">
    <type>transmission_interface/SimpleTransmission</type>
    <joint name="right_wheel_joint">
      <hardwareInterface>hardware_interface/EffortJointInterface</hardwareInterface>
    </joint>
    <actuator name="right_wheel_motor"/>
  </transmission>

  <link name="hokuyo">
    <inertial>
      <mass value="0.12165899018953562"/>
      <origin rpy="0 0 0" xyz="0 0 0"/>
      <inertia ixx="0.0005465720316521868" ixy="-5.224604443057849e-07" ixz="8.074887463142405e-07" iyy="0.0003984755097155271" iyz="0.00022241005016257183" izz="0.00018762073734616868"/>
    </inertial>
    <collision name="hokuyo_collision">
      <origin xyz="0 0 0.025"/>
      <geometry>
        <mesh filename="$(find interfearence-description)/meshes/CAD/hokuyo.stl" scale="0.001 0.001 0.001"/>
      </geometry>
    </collision>
    <visual name="hokuyo_visual">
      <origin xyz="0 0 0.025"/>
      <geometry>
        <mesh filename="$(find interfearence-description)/meshes/CAD/hokuyo.stl" scale="0.001 0.001 0.001"/>
      </geometry>
      <material name="black"/>
    </visual>
  </link>

  <gazebo reference="hokuyo">
    <sensor type="gpu_ray" name="hokuyo_sensor">
      <pose>0 0 0 0 0 0</pose>
      <visualize>true</visualize>
      <always_on>1</always_on>
      <update_rate>30</update_rate>
      <ray>
        <scan>
          <horizontal>
            <samples>640</samples>
            <resolution>1</resolution>
            <min_angle>-2.0944</min_angle>
            <max_angle>2.0944</max_angle>
          </horizontal>
        </scan>
        <range>
          <min>0.08</min>
          <max>2</max>
          <resolution>0.01</resolution>
        </range>
        <noise>
          <type>gaussian</type>
          <mean>0.0</mean>
          <stddev>0.01</stddev>
        </noise>
      </ray>
      <plugin name="laser"
              filename="libgazebo_ros_gpu_laser.so">
        <topicName>laser_scan</topicName>
        <frameName>hokuyo</frameName>
      </plugin>
    </sensor>
    <material>Gazebo/Black</material>
  </gazebo>

  <joint name="hokuyo_joint" type="fixed">
    <parent link="base_footprint"/>
    <child link="hokuyo"/>
    <origin rpy="0 -0.03 -1.57" xyz="-8.000e-05 -3.485e-02  2.744e-02"/>
  </joint>

  <link name="rear_right_line_sensor">
    <inertial>
      <mass value="0.0012857111617293646"/>
      <origin rpy="0 0 0" xyz="0 0 0"/>
      <inertia ixx="1.0390090598296027e-05" ixy="1.0306058746383977e-05" ixz="1.3290472306358516e-08" iyy="1.0248317234475216e-05" iyz="-1.3413016075006853e-08" izz="2.063758324264526e-05"/>
    </inertial>
    <collision name="rear_right_line_sensor_collision">
      <geometry>
        <mesh filename="$(find interfearence-description)/meshes/CAD/rear_right_line_sensor.stl" scale="0.001 0.001 0.001"/>
      </geometry>
    </collision>
    <visual name="rear_right_line_sensor_visual">
      <geometry>
        <mesh filename="$(find interfearence-description)/meshes/CAD/rear_right_line_sensor.stl" scale="0.001 0.001 0.001"/>
      </geometry>
      <material name="red"/>
    </visual>
  </link>

  <gazebo reference="rear_right_line_sensor">
    <sensor name="rear_right_line_sensor_sensor" type="camera">
      <camera name="rear_right_camera">
        <image>
          <width>1</width>
          <height>1</height>
          <format>R8G8B8</format>
        </image>
        <clip>
          <near>0.002</near>
        </clip>
      </camera>
      <plugin name="rear_right_edge_detector_plugin" 
              filename="libarena_edge_detection_plugin.so">
        <cameraName>rear_right_camera</cameraName>
        <alwaysOn>true</alwaysOn>
        <updateRate>30</updateRate>
        <imageTopicName>rgb/image_raw</imageTopicName>
        <cameraInfoTopicName>rgb/camera_info</cameraInfoTopicName>
        <frameName>/$(arg robotns)/rear_right_line_sensor</frameName>
        <topicName>/$(arg robotns)/edge_sensors/rear_right</topicName>
        <upperThreshhold>0.5</upperThreshhold>
        <lowerThreshhold>0.4</lowerThreshhold>
      </plugin>
    </sensor>
    <material>Gazebo/Red</material>
  </gazebo>

  <joint name="rear_right_line_sensor_joint" type="fixed">
    <parent link="base_footprint"/>
    <child link="rear_right_line_sensor"/>
    <origin rpy="0 0 0" xyz="-0.08925  0.08981  0.00011"/>
  </joint>

  <link name="rear_left_line_sensor">
    <inertial>
      <mass value="0.0012857111617293644"/>
      <origin rpy="0 0 0" xyz="0 0 0"/>
      <inertia ixx="1.0390090598296025e-05" ixy="-1.0306058746383974e-05" ixz="-1.3290472306358501e-08" iyy="1.0248317234475215e-05" iyz="-1.3413016075006833e-08" izz="2.063758324264526e-05"/>
    </inertial>
    <collision name="rear_left_line_sensor_collision">
      <geometry>
        <mesh filename="$(find interfearence-description)/meshes/CAD/rear_left_line_sensor.stl" scale="0.001 0.001 0.001"/>
      </geometry>
    </collision>
    <visual name="rear_left_line_sensor_visual">
      <geometry>
        <mesh filename="$(find interfearence-description)/meshes/CAD/rear_left_line_sensor.stl" scale="0.001 0.001 0.001"/>
      </geometry>
      <material name="red"/>
    </visual>
  </link>

  <gazebo reference="rear_left_line_sensor">
    <sensor name="rear_left_line_sensor_sensor" type="camera">
      <camera name="rear_left_camera">
        <image>
          <width>1</width>
          <height>1</height>
          <format>R8G8B8</format>
        </image>
        <clip>
          <near>0.002</near>
        </clip>
      </camera>
      <plugin name="rear_left_edge_detector_plugin" 
              filename="libarena_edge_detection_plugin.so">
        <cameraName>rear_left_camera</cameraName>
        <alwaysOn>true</alwaysOn>
        <updateRate>30</updateRate>
        <imageTopicName>rgb/image_raw</imageTopicName>
        <cameraInfoTopicName>rgb/camera_info</cameraInfoTopicName>
        <frameName>/$(arg robotns)/rear_left_line_sensor</frameName>
        <topicName>/$(arg robotns)/edge_sensors/rear_left</topicName>
        <upperThreshhold>0.5</upperThreshhold>
        <lowerThreshhold>0.4</lowerThreshhold>
      </plugin>
    </sensor>
    <material>Gazebo/Red</material>
  </gazebo>

  <joint name="rear_left_line_sensor_joint" type="fixed">
    <parent link="base_footprint"/>
    <child link="rear_left_line_sensor"/>
    <origin rpy="0 0 0" xyz="0.08925 0.08981 0.00011"/>
  </joint>

</robot>
