<?xml version="1.0"?>
<robot name="interfearence">
  <link name="base_link">
    <visual>
      <geometry>
        <box size="0.195 0.195 0.05"/>
      </geometry>
    </visual>
    <collision>
      <geometry>
        <box size="0.165 0.195 0.05"/>
      </geometry>
    </collision>
  </link>

  <link name="left_wheel">
    <visual>
      <geometry>
        <cylinder length="0.0525" radius="0.035"/>
      </geometry>
    </visual>
    <collision>
      <geometry>
        <cylinder length="0.0525" radius="0.035"/>
      </geometry>
    </collision>
  </link>

  <joint name="left_wheel_joint" type="revolute">
    <parent link="base_link"/>
    <child link="left_wheel"/>
    <axis xyz="0 0 1"/>
    <origin xyz="-0.0775 -0.05325 0.005" rpy="1.57079679 0 0"/>
    <limit effort="150.79" 
           lower="-3.1415926" 
           upper="3.1415926" 
           velocity="188.5"/>
  </joint>

  <link name="right_wheel">
    <visual>
      <geometry>
        <cylinder length="0.0525" radius="0.035"/>
      </geometry>
    </visual>
    <collision>
      <geometry>
        <cylinder length="0.0525" radius="0.035"/>
      </geometry>
    </collision>
  </link>

  <joint name="right_wheel_joint" type="revolute">
    <parent link="base_link"/>
    <child link="right_wheel"/>
    <axis xyz="0 0 1"/>
    <origin xyz="-0.0775 0.05325 0.005" rpy="1.57079679 0 0"/>
    <limit effort="150.79" 
           lower="-3.1415926" 
           upper="3.1415926" 
           velocity="188.5"/>
  </joint>
</robot>
