<?xml version="1.0"?>
<robot name="interfearence">
  <!-- dummy link as Gazebo doesn't allow the base link to have an inertial value -->
  <link name="base_link"/>

  <gazebo>
    <!-- plugin to allow the robot to interface with ros_control -->
    <plugin name="gazebo_ros_control" filename="libgazebo_ros_control.so">
      <robotNamespace>/</robotNamespace>
    </plugin>
    <self_collide>false</self_collide>
  </gazebo>

  <link name="chassis">
    <visual>
      <geometry>
        <box size="0.195 0.195 0.05"/>
      </geometry>
    </visual>
    <collision>
      <geometry>
        <box size="0.195 0.195 0.05"/>
      </geometry>
    </collision>
    <inertial>
      <origin xyz="0 0 0" rpy="0 0 0"/>
      <mass value="2.7"/>
      <inertia
      ixx="0.009118125"
      ixy="0"
      ixz="0"
      iyy="0.009118125"
      iyz="0"
      izz="0.01711125"/>
    </inertial>
  </link>

  <gazebo reference="chassis">
    <mu1>0.2</mu1>
    <mu2>0.2</mu2>
    <maxVel>0.0</maxVel>
    <minDepth>0.001</minDepth>
  </gazebo>

  <joint name="chassis_joint" type="fixed">
    <parent link="base_link"/>
    <child link="chassis"/>
  </joint>

  <link name="hokuyo">
    <visual>
      <geometry>
        <box size="0.05 0.05 0.07"/>
      </geometry>
    </visual>
    <inertial>
      <origin xyz="0 0 0" rpy="0 0 0"/>
      <mass value="0.0"/>
      <inertia
      ixx="0"
      ixy="0"
      ixz="0"
      iyy="0"
      iyz="0"
      izz="0"/>
    </inertial>
  </link>

  <gazebo reference="hokuyo">
    <sensor type="gpu_ray" name="hokuyo_sensor">
      <pose>0 0 0 0 0 0</pose>
      <visualize>true</visualize>
      <always_on>1</always_on>
      <update_rate>30</update_rate>
      <ray>
        <scan>
          <horizontal>
            <samples>640</samples>
            <resolution>1</resolution>
            <min_angle>-2.0944</min_angle>
            <max_angle>2.0944</max_angle>
          </horizontal>
        </scan>
        <range>
          <min>0.08</min>
          <max>10</max>
          <resolution>0.01</resolution>
        </range>
        <noise>
          <type>gaussian</type>
          <mean>0.0</mean>
          <stddev>0.01</stddev>
        </noise>
      </ray>
      <plugin name="laser"
              filename="libgazebo_ros_gpu_laser.so">
        <topicName>laser_scan</topicName>
        <frameName>hokuyo</frameName>
      </plugin>
    </sensor>
  </gazebo>

  <joint name="hokuyo_joint" type="fixed">
    <parent link="chassis"/>
    <child link="hokuyo"/>
    <origin xyz="0 0 0.035"/>
  </joint>

  <link name="left_wheel">
    <visual>
      <geometry>
        <cylinder length="0.0525" radius="0.035"/>
      </geometry>
    </visual>
    <collision>
      <geometry>
        <cylinder length="0.0525" radius="0.035"/>
      </geometry>
    </collision>
    <inertial>
      <origin xyz="0 0 0" rpy="0 0 0"/>
      <mass value="0.150"/>
      <inertia
      ixx="0.00008171562"
      ixy="0"
      ixz="0"
      iyy="0.00008171562"
      iyz="0"
      izz="0.000091875"/>
    </inertial>
  </link>

  <gazebo reference="left_wheel">
    <mu1>0.9</mu1>
    <mu2>0.9</mu2>
    <maxVel>0.0</maxVel>
    <minDepth>0.003</minDepth>
  </gazebo>

  <joint name="left_wheel_joint" type="continuous">
    <parent link="chassis"/>
    <child link="left_wheel"/>
    <axis xyz="0 0 -1"/>
    <origin xyz="-0.0775 0.05325 0.005" rpy="1.57079679 0 0"/>
    <limit effort="0.8" 
           velocity="188.5"/>
  </joint>

  <transmission name="left_wheel_transmission">
    <type>transmission_interface/SimpleTransmission</type>
    <joint name="left_wheel_joint">
      <hardwareInterface>hardware_interface/EffortJointInterface</hardwareInterface>
    </joint>
    <actuator name="left_wheel_motor"/>
  </transmission>

  <link name="right_wheel">
    <visual>
      <geometry>
        <cylinder length="0.0525" radius="0.035"/>
      </geometry>
    </visual>
    <collision>
      <geometry>
        <cylinder length="0.0525" radius="0.035"/>
      </geometry>
    </collision>
    <inertial>
      <origin xyz="0 0 0" rpy="0 0 0"/>
      <mass value="0.150"/>
      <inertia
      ixx="0.00008171562"
      ixy="0"
      ixz="0"
      iyy="0.00008171562"
      iyz="0"
      izz="0.000091875"/>
    </inertial>
  </link>

  <gazebo link="right_wheel">
    <mu1>0.9</mu1>
    <mu2>0.9</mu2>
    <maxVel>0.0</maxVel>
    <minDepth>0.003</minDepth>
  </gazebo>

  <joint name="right_wheel_joint" type="continuous">
    <parent link="chassis"/>
    <child link="right_wheel"/>
    <axis xyz="0 0 -1"/>
    <origin xyz="-0.0775 -0.05325 0.005" rpy="1.57079679 0 0"/>
    <limit effort="0.8" 
           velocity="188.5"/>
  </joint>

  <transmission name="right_wheel_transmission">
    <type>transmission_interface/SimpleTransmission</type>
    <joint name="right_wheel_joint">
      <hardwareInterface>hardware_interface/EffortJointInterface</hardwareInterface>
    </joint>
    <actuator name="right_wheel_motor"/>
  </transmission>
</robot>
